<?xml version="1.0" ?>
<!-- =================================================================================== -->
<!-- |    This document was autogenerated by xacro from majager.xacro                  | -->
<!-- |    EDITING THIS FILE BY HAND IS NOT RECOMMENDED                                 | -->
<!-- =================================================================================== -->
<robot name="majager">
  <material name="silver">
    <color rgba="0.700 0.700 0.700 1.000"/>
  </material>
  <material name="Yellow">
    <color rgba="0.93 0.76 0.0 1.0"/>
  </material>
  <material name="Grey">
    <color rgba="0.7 0.7 0.7 1.0"/>
  </material>
  <material name="Black">
    <color rgba="0.0 0.0 0.0 1.0"/>
  </material>
  <gazebo>
    <plugin filename="libgazebo_ros_control.so" name="gazebo_ros_control">
      <robotSimType>gazebo_ros_control/DefaultRobotHWSim</robotSimType>
      <robotNamespace>/majager</robotNamespace>
      <robotParam>robot_description</robotParam>
      <legacyModeNS>true</legacyModeNS>
    </plugin>
  </gazebo>
  <gazebo reference="base_link">
    <material>Gazebo/Silver</material>
    <mu1>0.2</mu1>
    <mu2>0.2</mu2>
    <selfCollide>true</selfCollide>
    <gravity>true</gravity>
  </gazebo>
  <gazebo reference="Link1_1">
    <material>Gazebo/Silver</material>
    <mu1>0.2</mu1>
    <mu2>0.2</mu2>
    <selfCollide>true</selfCollide>
  </gazebo>
  <gazebo reference="Link2_1">
    <material>Gazebo/Silver</material>
    <mu1>0.2</mu1>
    <mu2>0.2</mu2>
    <selfCollide>true</selfCollide>
  </gazebo>
  <gazebo reference="Link3_1">
    <material>Gazebo/Silver</material>
    <mu1>0.2</mu1>
    <mu2>0.2</mu2>
    <selfCollide>true</selfCollide>
  </gazebo>
  <gazebo reference="Link4_1">
    <material>Gazebo/Silver</material>
    <mu1>0.2</mu1>
    <mu2>0.2</mu2>
    <selfCollide>true</selfCollide>
  </gazebo>
  <gazebo reference="Link5_1">
    <material>Gazebo/Silver</material>
    <mu1>0.2</mu1>
    <mu2>0.2</mu2>
    <selfCollide>true</selfCollide>
  </gazebo>
  <gazebo reference="Link6_1">
    <material>Gazebo/Silver</material>
    <mu1>0.2</mu1>
    <mu2>0.2</mu2>
    <selfCollide>true</selfCollide>
  </gazebo>
  <gazebo reference="Base_Gripper_1">
    <material>Gazebo/Silver</material>
    <mu1>0.2</mu1>
    <mu2>0.2</mu2>
    <selfCollide>true</selfCollide>
  </gazebo>
  <gazebo reference="Gripper_Left_1">
    <material>Gazebo/White</material>
    <mu1>1.0</mu1>
    <mu2>1.0</mu2>
    <kp>1000000.0</kp>
    <kd>1.0</kd>
    <minDepth>0.001</minDepth>
    <!--maxVel>0.1</maxVel>
  <fdir1>1 0 0</fdir1-->
  </gazebo>
  <gazebo reference="Gripper_Right_1">
    <material>Gazebo/White</material>
    <mu1>1.0</mu1>
    <mu2>1.0</mu2>
    <kp>1000000.0</kp>
    <kd>1.0</kd>
    <minDepth>0.001</minDepth>
    <!--maxVel>0.1</maxVel>
  <fdir1>1 0 0</fdir1-->
  </gazebo>
  <!-- World frame (for Gazebo) -->
  <link name="world"/>
  <!-- Arm fixed to world frame  -->
  <joint name="world__base_link" type="fixed">
    <parent link="world"/>
    <child link="base_link"/>
    <origin rpy="0 0 0" xyz="0 0 0"/>
  </joint>
  <link name="base_link">
    <inertial>
      <mass value="351.2471728207797"/>
      <origin rpy="0 0 0" xyz="-7.089415568373423e-17 -0.022734689380917134 0.15849931820776944"/>
      <inertia ixx="7.803246" ixy="0" ixz="0" iyy="6.469342" iyz="0" izz="7.933037"/>
    </inertial>
    <collision>
      <origin rpy="0 0 0" xyz="0 0 0"/>
      <geometry>
        <mesh filename="package://majager_description/meshes/base_link.stl" scale="0.001 0.001 0.001"/>
      </geometry>
    </collision>
    <visual>
      <origin rpy="0 0 0" xyz="0 0 0"/>
      <geometry>
        <mesh filename="package://majager_description/meshes/base_link.stl" scale="0.001 0.001 0.001"/>
      </geometry>
      <material name="Black"/>
    </visual>
  </link>
  <joint name="Base_to_Link1" type="continuous">
    <axis xyz="-0.0 -0.0 1.0"/>
    <limit effort="100" velocity="100"/>
    <origin rpy="0 0 0" xyz="0.0 0.0 0.33"/>
    <parent link="base_link"/>
    <child link="Link1_1"/>
  </joint>
  <transmission name="Base_to_Link1_tran">
    <type>transmission_interface/SimpleTransmission</type>
    <joint name="Base_to_Link1">
      <hardwareInterface>hardware_interface/PositionJointInterface</hardwareInterface>
    </joint>
    <actuator name="Base_to_Link1_actr">
      <hardwareInterface>hardware_interface/PositionJointInterface</hardwareInterface>
      <mechanicalReduction>1</mechanicalReduction>
    </actuator>
  </transmission>
  <link name="Link1_1">
    <inertial>
      <mass value="5.52547968640361"/>
      <origin rpy="0 0 0" xyz="0.010990144273109063 0.0882068365110577 0.13577480191631508"/>
      <inertia ixx="3.160703" ixy="-0.14808" ixz="-0.151302" iyy="1.945221" iyz="-1.098862" izz="2.215367"/>
    </inertial>
    <collision>
      <origin rpy="0 0 0" xyz="0.0 0.0 -0.33"/>
      <geometry>
        <mesh filename="package://majager_description/meshes/Link1_1.stl" scale="0.001 0.001 0.001"/>
      </geometry>
    </collision>
    <visual>
      <origin rpy="0 0 0" xyz="0.0 0.0 -0.33"/>
      <geometry>
        <mesh filename="package://majager_description/meshes/Link1_1.stl" scale="0.001 0.001 0.001"/>
      </geometry>
      <material name="Yellow"/>
    </visual>
  </link>
  <joint name="Link1_to_Link2" type="revolute">
    <axis xyz="1.0 0.0 0.0"/>
    <limit effort="100" lower="-3.3161255" upper="1.3963" velocity="100"/>
    <origin rpy="0.5235987756 0 0" xyz="0.09 0.2 0.25"/>
    <parent link="Link1_1"/>
    <child link="Link2_1"/>
  </joint>
  <transmission name="Link1_to_Link2_tran">
    <type>transmission_interface/SimpleTransmission</type>
    <joint name="Link1_to_Link2">
      <hardwareInterface>hardware_interface/PositionJointInterface</hardwareInterface>
    </joint>
    <actuator name="Link1_to_Link2_actr">
      <hardwareInterface>hardware_interface/PositionJointInterface</hardwareInterface>
      <mechanicalReduction>1</mechanicalReduction>
    </actuator>
  </transmission>
  <link name="Link2_1">
    <inertial>
      <mass value="5.82400607636134"/>
      <origin rpy="0 0 0" xyz="0.0953874109671839 -1.1102230246251565e-14 0.3999420840487563"/>
      <inertia ixx="16.907224" ixy="0" ixz="0" iyy="16.692266" iyz="0" izz="0.659521"/>
    </inertial>
    <collision>
      <origin rpy="0 0 0" xyz="-0.09 -0.2 -0.58"/>
      <geometry>
        <mesh filename="package://majager_description/meshes/Link2_1.stl" scale="0.001 0.001 0.001"/>
      </geometry>
    </collision>
    <visual>
      <origin rpy="0 0 0" xyz="-0.09 -0.2 -0.58"/>
      <geometry>
        <mesh filename="package://majager_description/meshes/Link2_1.stl" scale="0.001 0.001 0.001"/>
      </geometry>
      <material name="Yellow"/>
    </visual>
  </link>
  <joint name="Link2_to_Link3" type="revolute">
    <axis xyz="1.0 -0.0 0.0"/>
    <limit effort="100" lower="-0.7" upper="4.2" velocity="100"/>
    <origin rpy="-0.5235987756 0 0" xyz="0.0 0.0 0.8"/>
    <parent link="Link2_1"/>
    <child link="Link3_1"/>
  </joint>
  <transmission name="Link2_to_Link3_tran">
    <type>transmission_interface/SimpleTransmission</type>
    <joint name="Link2_to_Link3">
      <hardwareInterface>hardware_interface/PositionJointInterface</hardwareInterface>
    </joint>
    <actuator name="Link2_to_Link3_actr">
      <hardwareInterface>hardware_interface/PositionJointInterface</hardwareInterface>
      <mechanicalReduction>1</mechanicalReduction>
    </actuator>
  </transmission>
  <link name="Link3_1">
    <inertial>
      <mass value="2.14016041688751"/>
      <origin rpy="0 0 0" xyz="-0.08225410153755812 0.09831042517527713 0.08665205846011848"/>
      <inertia ixx="4.813544" ixy="0.160871" ixz="0.096164" iyy="0.718651" iyz="-0.721581" izz="4.447232"/>
    </inertial>
    <collision>
      <origin rpy="0 0 0" xyz="-0.09 -0.2 -1.38"/>
      <geometry>
        <mesh filename="package://majager_description/meshes/Link3_1.stl" scale="0.001 0.001 0.001"/>
      </geometry>
    </collision>
    <visual>
      <origin rpy="0 0 0" xyz="-0.09 -0.2 -1.38"/>
      <geometry>
        <mesh filename="package://majager_description/meshes/Link3_1.stl" scale="0.001 0.001 0.001"/>
      </geometry>
      <material name="Yellow"/>
    </visual>
  </link>
  <joint name="Link3_to_Link4" type="continuous">
    <axis xyz="0.0 1.0 0.0"/>
    <limit effort="100" velocity="100"/>
    <origin rpy="0 0 0" xyz="-0.09 0.35 0.13"/>
    <parent link="Link3_1"/>
    <child link="Link4_1"/>
  </joint>
  <transmission name="Link3_to_Link4_tran">
    <type>transmission_interface/SimpleTransmission</type>
    <joint name="Link3_to_Link4">
      <hardwareInterface>hardware_interface/PositionJointInterface</hardwareInterface>
    </joint>
    <actuator name="Link3_to_Link4_actr">
      <hardwareInterface>hardware_interface/PositionJointInterface</hardwareInterface>
      <mechanicalReduction>1</mechanicalReduction>
    </actuator>
  </transmission>
  <link name="Link4_1">
    <inertial>
      <mass value="2.036896395207224"/>
      <origin rpy="0 0 0" xyz="-0.01381923652259904 0.1126422845962809 1.5576813499063036e-06"/>
      <inertia ixx="0.061572" ixy="0.010471" ixz="-0.0" iyy="0.018205" iyz="-1e-06" izz="0.067201"/>
    </inertial>
    <collision>
      <origin rpy="0 0 0" xyz="-0.0 -0.55 -1.51"/>
      <geometry>
        <mesh filename="package://majager_description/meshes/Link4_1.stl" scale="0.001 0.001 0.001"/>
      </geometry>
    </collision>
    <visual>
      <origin rpy="0 0 0" xyz="-0.0 -0.55 -1.51"/>
      <geometry>
        <mesh filename="package://majager_description/meshes/Link4_1.stl" scale="0.001 0.001 0.001"/>
      </geometry>
      <material name="Black"/>
    </visual>
  </link>
  <joint name="Link4_to_Link5" type="revolute">
    <axis xyz="1.0 -0.0 0.0"/>
    <limit effort="100" lower="-0.87266" upper="4.01426" velocity="100"/>
    <origin rpy="0 0 0" xyz="-0.085 0.415 0.0"/>
    <parent link="Link4_1"/>
    <child link="Link5_1"/>
  </joint>
  <transmission name="Link4_to_Link5_tran">
    <type>transmission_interface/SimpleTransmission</type>
    <joint name="Link4_to_Link5">
      <hardwareInterface>hardware_interface/PositionJointInterface</hardwareInterface>
    </joint>
    <actuator name="Link4_to_Link5_actr">
      <hardwareInterface>hardware_interface/PositionJointInterface</hardwareInterface>
      <mechanicalReduction>1</mechanicalReduction>
    </actuator>
  </transmission>
  <link name="Link5_1">
    <inertial>
      <mass value="1.83303077561953"/>
      <origin rpy="0 0 0" xyz="-0.02715869025322588 -5.218048215738236e-15 -0.08759357763589937"/>
      <inertia ixx="0.167562" ixy="0" ixz="-0.016099" iyy="0.227483" iyz="0" izz="0.091889"/>
    </inertial>
    <collision>
      <origin rpy="0 0 0" xyz="0.085 -0.965 -1.51"/>
      <geometry>
        <mesh filename="package://majager_description/meshes/Link5_1.stl" scale="0.001 0.001 0.001"/>
      </geometry>
    </collision>
    <visual>
      <origin rpy="0 0 0" xyz="0.085 -0.965 -1.51"/>
      <geometry>
        <mesh filename="package://majager_description/meshes/Link5_1.stl" scale="0.001 0.001 0.001"/>
      </geometry>
      <material name="Yellow"/>
    </visual>
  </link>
  <joint name="Link5_to_Link6" type="prismatic">
    <axis xyz="0.0 -0.0 -1.0"/>
    <limit effort="100" lower="0.0" upper="0.3" velocity="100"/>
    <origin rpy="0 0 0" xyz="0.085 0.0 -0.25"/>
    <parent link="Link5_1"/>
    <child link="Link6_1"/>
  </joint>
  <transmission name="Link5_to_Link6_tran">
    <type>transmission_interface/SimpleTransmission</type>
    <joint name="Link5_to_Link6">
      <hardwareInterface>hardware_interface/PositionJointInterface</hardwareInterface>
    </joint>
    <actuator name="Link5_to_Link6_actr">
      <hardwareInterface>hardware_interface/PositionJointInterface</hardwareInterface>
      <mechanicalReduction>1</mechanicalReduction>
    </actuator>
  </transmission>
  <link name="Link6_1">
    <inertial>
      <mass value="1.9701696869512575"/>
      <origin rpy="0 0 0" xyz="-1.462357275260921e-16 -8.215650382226158e-15 -0.10789050337311945"/>
      <inertia ixx="0.009725" ixy="0" ixz="0.0" iyy="0.009725" iyz="0" izz="0.001313"/>
    </inertial>
    <collision>
      <origin rpy="0 0 0" xyz="0.0 -0.965 -1.26"/>
      <geometry>
        <mesh filename="package://majager_description/meshes/Link6_1.stl" scale="0.001 0.001 0.001"/>
      </geometry>
    </collision>
    <visual>
      <origin rpy="0 0 0" xyz="0.0 -0.965 -1.26"/>
      <geometry>
        <mesh filename="package://majager_description/meshes/Link6_1.stl" scale="0.001 0.001 0.001"/>
      </geometry>
      <material name="Black"/>
    </visual>
  </link>
  <joint name="Link6_to_Base_Gripper" type="continuous">
    <axis xyz="-0.0 -0.0 -1.0"/>
    <limit effort="100" velocity="100"/>
    <origin rpy="0 0 0" xyz="0.0 0.0 -0.03"/>
    <parent link="Link6_1"/>
    <child link="Base_Gripper_1"/>
  </joint>
  <transmission name="Link6_to_Base_Gripper_tran">
    <type>transmission_interface/SimpleTransmission</type>
    <joint name="Link6_to_Base_Gripper">
      <hardwareInterface>hardware_interface/PositionJointInterface</hardwareInterface>
    </joint>
    <actuator name="Link6_to_Base_Gripper_actr">
      <hardwareInterface>hardware_interface/PositionJointInterface</hardwareInterface>
      <mechanicalReduction>1</mechanicalReduction>
    </actuator>
  </transmission>
  <link name="Base_Gripper_1">
    <inertial>
      <mass value="1.1700579922254057"/>
      <origin rpy="0 0 0" xyz="-1.309810703716444e-16 -8.215650382226158e-15 -0.014382845951966372"/>
      <inertia ixx="0.000268" ixy="0" ixz="0" iyy="0.003233" iyz="0" izz="1"/>
    </inertial>
    <collision>
      <origin rpy="0 0 0" xyz="0.0 -0.965 -1.23"/>
      <geometry>
        <mesh filename="package://majager_description/meshes/Base_Gripper_1.stl" scale="0.001 0.001 0.001"/>
      </geometry>
    </collision>
    <visual>
      <origin rpy="0 0 0" xyz="0.0 -0.965 -1.23"/>
      <geometry>
        <mesh filename="package://majager_description/meshes/Base_Gripper_1.stl" scale="0.001 0.001 0.001"/>
      </geometry>
      <material name="Black"/>
    </visual>
  </link>
  <joint name="Base_Gripper_to_Gripper_Right" type="prismatic">
    <axis xyz="1.0 -0.0 -0.0"/>
    <limit effort="100" lower="0.0" upper="0.065" velocity="100"/>
    <origin rpy="0 0 0" xyz="-0.09 0.0 -0.0225"/>
    <parent link="Base_Gripper_1"/>
    <child link="Gripper_Right_1"/>
  </joint>
  <transmission name="Base_Gripper_to_Gripper_Right_tran">
    <type>transmission_interface/SimpleTransmission</type>
    <joint name="Base_Gripper_to_Gripper_Right">
      <hardwareInterface>hardware_interface/PositionJointInterface</hardwareInterface>
    </joint>
    <actuator name="Base_Gripper_to_Gripper_Right_actr">
      <hardwareInterface>hardware_interface/PositionJointInterface</hardwareInterface>
      <mechanicalReduction>1</mechanicalReduction>
    </actuator>
  </transmission>
  <link name="Gripper_Right_1">
    <inertial>
      <mass value="0.6554750004678966"/>
      <origin rpy="0 0 0" xyz="0.012095808747128123 -2.786659791809143e-14 -0.03856287422397031"/>
      <inertia ixx="0.00044" ixy="-0.0" ixz="3e-05" iyy="0.000397" iyz="-0.0" izz="0.000125"/>
    </inertial>
    <collision>
      <origin rpy="0 0 0" xyz="0.09 -0.965 -1.2075"/>
      <geometry>
        <mesh filename="package://majager_description/meshes/Gripper_Right_1.stl" scale="0.001 0.001 0.001"/>
      </geometry>
    </collision>
    <visual>
      <origin rpy="0 0 0" xyz="0.09 -0.965 -1.2075"/>
      <geometry>
        <mesh filename="package://majager_description/meshes/Gripper_Right_1.stl" scale="0.001 0.001 0.001"/>
      </geometry>
      <material name="Grey"/>
    </visual>
  </link>
  <joint name="Base_Gripper_to_Gripper_Left" type="prismatic">
    <axis xyz="-1.0 0.0 0.0"/>
    <limit effort="100" lower="0.0" upper="0.065" velocity="100"/>
    <origin rpy="0 0 0" xyz="0.09 0.0 -0.0225"/>
    <parent link="Base_Gripper_1"/>
    <child link="Gripper_Left_1"/>
  </joint>
  <transmission name="Base_Gripper_to_Gripper_Left_tran">
    <type>transmission_interface/SimpleTransmission</type>
    <joint name="Base_Gripper_to_Gripper_Left">
      <hardwareInterface>hardware_interface/PositionJointInterface</hardwareInterface>
    </joint>
    <actuator name="Base_Gripper_to_Gripper_Left_actr">
      <hardwareInterface>hardware_interface/PositionJointInterface</hardwareInterface>
      <mechanicalReduction>1</mechanicalReduction>
    </actuator>
  </transmission>
  <link name="Gripper_Left_1">
    <inertial>
      <mass value="0.6554750004678964"/>
      <origin rpy="0 0 0" xyz="-0.012095808747128373 8.992806499463768e-15 -0.03856287422397009"/>
      <inertia ixx="0.00044" ixy="0" ixz="-3e-05" iyy="0.000397" iyz="0" izz="0.000125"/>
    </inertial>
    <collision>
      <origin rpy="0 0 0" xyz="-0.09 -0.965 -1.2075"/>
      <geometry>
        <mesh filename="package://majager_description/meshes/Gripper_Left_1.stl" scale="0.001 0.001 0.001"/>
      </geometry>
    </collision>
    <visual>
      <origin rpy="0 0 0" xyz="-0.09 -0.965 -1.2075"/>
      <geometry>
        <mesh filename="package://majager_description/meshes/Gripper_Left_1.stl" scale="0.001 0.001 0.001"/>
      </geometry>
      <material name="Grey"/>
    </visual>
  </link>
</robot>

